<?xml version="1.0"?>
<robot name="urdfbot" xmlns:xacro="http://ros.org/wiki/xacro">

    <xacro:property name="wheel_radius" value="0.07"/>
    <xacro:property name="wheel_length" value="0.05"/>
    <xacro:property name="linear_length" value="0.6435"/>

    <material name="blue">
        <color rgba="0.006 0.151 0.581 1"/>
    </material>

    <material name="white">
        <color rgba="1.0 0.91 0.827 1"/>
    </material>

    <link name="base_link">
        <visual>
            <origin rpy="0 0 0" xyz="0 0 0.22"/>
            <geometry>
                <box size="0.406 0.456 0.3"/>
            </geometry>
        </visual>
    </link>

    <link name="wheel_1">
        <visual>
            <origin rpy="0 1.571 1.571" xyz="0 0 0"/>
            <geometry>
                <cylinder radius="${0.07}" length="${0.05}"/>
            </geometry>
            <material name="white"/>
        </visual>
    </link>

    <joint name="base_link_to_wheel_1_joint" type="continuous">
        <origin xyz="-0.043 0.15 0.07" rpy="0 0 0"/>
        <parent link="base_link"/>
        <child link="wheel_1"/>
        <axis xyz="0 1 0"/>
    </joint>

    <link name="wheel_2">
        <visual>
            <origin rpy="0 1.571 1.571" xyz="0 0 0"/>
            <geometry>
                <cylinder radius="${0.07}" length="${0.05}"/>
            </geometry>
            <material name="white"/>
        </visual>
    </link>

    <joint name="base_link_to_wheel_2_joint" type="continuous">
        <origin xyz="-0.043 -0.15 0.07" rpy="0 0 0"/>
        <parent link="base_link"/>
        <child link="wheel_2"/>
        <axis xyz="0 1 0"/>
    </joint>

    <link name="linear_1">
        <visual>
            <origin rpy="0 0 0" xyz="0 0 0"/>
            <geometry>
                <cylinder radius="${0.03}" length="${0.6435}"/>
            </geometry>
            <material name="blue"/>
        </visual>
    </link>

    <joint name="base_link_to_linear_1_joint" type="prismatic">
        <origin xyz="-0.15 0.15 0.39375" rpy="0 0 0"/>
        <parent link="base_link"/>
        <child link="linear_1"/>
        <axis xyz="0 0 1"/>
        <limit effort="100" velocity="0" lower="0" upper="0.3"/>
    </joint>
    
    <link name="linear_2">
        <visual>
            <origin rpy="0 0 0" xyz="0 0 0"/>
            <geometry>
                <cylinder radius="${0.03}" length="${0.6435}"/>
            </geometry>
            <material name="blue"/>
        </visual>
    </link>

    <joint name="linear_1_to_linear_2_joint" type="fixed">
        <origin xyz="0 -0.3 0" rpy="0 0 0"/>
        <parent link="linear_1"/>
        <child link="linear_2"/>
    </joint>

    <link name="arm">
        <visual>
            <origin rpy="0 0 0" xyz="0 0 0"/>
            <geometry>
                <box size="0.5805 0.36 0.03"/>
            </geometry>
            <material name="blue"/>
        </visual>
    </link>

    <joint name="linear_1_to_arm_joint" type="fixed">
        <origin xyz="0.26025 -0.15 0.30675" rpy="0 0 0"/>
        <parent link="linear_1"/>
        <child link="arm"/>
    </joint>

</robot>